<?xml version="1.0"?>

<robot name="leap_right_dottip">
    <!-- <mujoco>
        <compiler meshdir="./meshes" balanceinertia="true" discardvisual="false" />
    </mujoco> -->

    <link name="base"/>

    <joint name="palm_joint" type="fixed">
        <parent link="base" />
        <child link="palm_lower" />
        <!-- <origin xyz="0.07 0.022392243865100525113 0.0" rpy="0 0 0" /> -->
        <!-- <origin xyz="0.100 0.0224 0.020" rpy="0 0 0" /> -->
        <origin xyz="0.110 0.0424 0.010" rpy="0 0 0" />
    </joint>


    <link name="palm_lower">
        <visual>
            <origin xyz="-0.020095249652862544332 0.025757756134899473244 -0.034722403578460216134" rpy="0 -0 0" />
            <geometry>
                <mesh filename="./meshes/palm_lower.stl"/>
            </geometry>
            <material name="palm_lower_material">
                <color rgba="0.60392156862745094426 0.14901960784313725283 0.14901960784313725283 1.0"/>
            </material>
        </visual>
        <!-- <collision>
            <origin xyz="-0.020095249652862544332 0.025757756134899473244 -0.034722403578460216134" rpy="0 -0 0" />
            <geometry>
                <mesh filename="./meshes/palm_lower.stl"/>
            </geometry>
        </collision> -->
        <inertial>
            <origin xyz="0 0 0" rpy="0 0 0"/>
            <mass value="0.237" />
            <inertia ixx="0.000354094" ixy="-0.000001193" ixz="-0.000002445" iyy="0.000260915" iyz="-0.000002905" izz="0.000529257" />
        </inertial>
    </link>

    <link name="mcp_joint">
        <visual>
            <origin xyz="0.0084069022611744960438 0.0077662438597169954416 0.014657354985032912051" rpy="0 0 0" />
            <geometry>
                <mesh filename="./meshes/mcp_joint.stl"/>
            </geometry>
            <material name="mcp_joint_material">
                <color rgba="0.86666666666666669627 0.86666666666666669627 0.050980392156862744391 1.0"/>
            </material>
        </visual>
        <!-- <collision>
            <origin xyz="0.0084069022611744960438 0.0077662438597169954416 0.014657354985032912051" rpy="0 0 0" />
            <geometry>
                <mesh filename="./meshes/mcp_joint.stl"/>
            </geometry>
        </collision> -->
        <inertial>
            <origin xyz="0 0 0" rpy="0 0 0"/>
            <mass value="0.044" />
            <inertia ixx="0.000011499" ixy="0.000003049" ixz="0.000000121" iyy="0.000007796" iyz="0.000000112" izz="0.000014759" />
        </inertial>
    </link>

    <link name="pip">
        <visual>
            <origin xyz="0.0096433630922713280131 0.00029999999999998951117 0.00078403401041737645627" rpy="-1.570796326794896558 -1.570796326794896336 0" />
            <geometry>
                <mesh filename="./meshes/pip.stl"/>
            </geometry>
            <material name="pip_material">
                <color rgba="0.74901960784313725839 0.74901960784313725839 0.74901960784313725839 1.0"/>
            </material>
        </visual>
        <!-- <collision>
            <origin xyz="0.0096433630922713280131 0.00029999999999998951117 0.00078403401041737645627" rpy="-1.570796326794896558 -1.570796326794896336 0" />
            <geometry>
                <mesh filename="./meshes/pip.stl"/>
            </geometry>
        </collision> -->
        <inertial>
            <origin xyz="0 0 0" rpy="0 0 0"/>
            <mass value="0.032" />
            <inertia ixx="0.000004798" ixy="0.000000012" ixz="0.000000004" iyy="0.000002862" iyz="0.000000011" izz="0.000004234" />
        </inertial>
    </link>

    <link name="dip">
        <visual>
            <origin xyz="0.021133352895225002849 -0.0084321191467048792201 0.0097850881620952408213" rpy="-3.141592653589793116 0 0" />
            <geometry>
                <mesh filename="./meshes/dip.stl"/>
            </geometry>
            <material name="dip_material">
                <color rgba="0.86666666666666669627 0.86666666666666669627 0.050980392156862744391 1.0"/>
            </material>
        </visual>
        <!-- <collision>
            <origin xyz="0.021133352895225002849 -0.0084321191467048792201 0.0097850881620952408213" rpy="-3.141592653589793116 0 0" />
            <geometry>
                <mesh filename="./meshes/dip.stl"/>
            </geometry>0.10
        </collision> -->
        <inertial>
            <origin xyz="0 0 0" rpy="0 0 0"/>
            <mass value="0.037" />
            <inertia ixx="0.000005542" ixy="-0.000000607" ixz="-0.000000017" iyy="0.000005727" iyz="-0.000000023" izz="0.000006682" />
        </inertial>
    </link>

    <link name="tip_base">
        <visual>
            <origin xyz="0 -0.014 0.014499" rpy="3.14159 0 0 " />
            <geometry>
                <mesh filename="./meshes/tip_base.stl"/>
            </geometry>
            <material name="tip_base_material">
                <color rgba="0.46777 0.86666666666666669627 0.050980392156862744391 1.0"/>
            </material>
        </visual>
        <!-- <collision>
            <origin xyz="0 -0.014 0.014499" rpy="3.14159 0 0 " />
            <geometry>
                <mesh filename="./meshes/tip_base.stl"/>
            </geometry>
        </collision> -->
        <inertial>
            <origin xyz="0 0 0" rpy="0 0 0"/>
            <mass value="0.008" />
            <inertia ixx="0.000003368" ixy="0.000000115" ixz="0" iyy="0.000001556" iyz="0" izz="0.000002863" />
        </inertial>
    </link>

    <link name="fingertip_if">
        <visual>
            <origin xyz="0 0 0" rpy="3.14159 0 -1.57080" />
            <geometry>
                <mesh filename="./meshes/DotTip.stl"/>
            </geometry>
            <material name="fingertip_material">
                <color rgba="0.8627 0.7868 0.5568 1.0"/>
            </material>
        </visual>
        <!-- <collision>
            <origin xyz="0 0 0" rpy="3.14159 0 -1.57080" />
            <geometry>
                <mesh filename="./meshes/DotTip.stl"/>
            </geometry>
        </collision> -->
        <inertial>
            <origin xyz="0 0 0" rpy="0 0 0"/>
            <mass value="0.016" />
            <inertia ixx="0.000003368" ixy="0.000000115" ixz="0" iyy="0.000001556" iyz="0" izz="0.000002863" />
        </inertial>
    </link>



    <joint name="j00" type="revolute">
        <origin xyz="-0.012200000000000007713 0.038099999999999994982 0.014500000000000000736" rpy="-1.570796326794896558 0 1.5707963267948943376" />
        <parent link="mcp_joint" />
        <child link="pip" />
        <axis xyz="0 0 -1"/>
        <limit effort="0.95" velocity="8.48" lower = "-0.80" upper = "0.60"/>
        <!-- <limit effort="0.95" velocity="8.48" lower = "-1.047" upper = "1.047"/> -->
        <joint_properties friction="0.0"/>
    </joint>

    <joint name="j01" type="revolute">
        <origin xyz="-0.0070952496528625457958 0.023057756134899472233 -0.01872240357846021927" rpy="1.5707963267948950037 1.5707963267948945596 0" />
        <parent link="palm_lower" />
        <child link="mcp_joint" />
        <axis xyz="0 0 -1"/>
        <!-- <limit effort="0.95" velocity="8.48" lower = "-0.314" upper = "2.23"/> -->
        <limit effort="0.95" velocity="8.48" lower = "-0.0" upper = "2.23"/>
        <joint_properties friction="0.0"/>
    </joint>

    <joint name="j02" type="revolute">
        <origin xyz="0.01499999999999996822 0.014299999999999904801 -0.012999999999999824196" rpy="1.5707963267948958919 -1.570796326794896336 0" />
        <parent link="pip" />
        <child link="dip" />
        <axis xyz="0 0 -1"/>
        <limit effort="0.95" velocity="8.48" lower = "0.00" upper = "1.885"/>
        <joint_properties friction="0.0"/>
    </joint>

    <joint name="j03" type="revolute">
        <origin xyz="0 -0.036100004210367367397 0 " rpy="0 0 0 " />
        <!-- <origin xyz="0 0 0 " rpy="0 0 0 " /> -->
        <parent link="dip" />
        <child link="tip_base" />
        <axis xyz="0 0 -1"/>
        <limit effort="0.95" velocity="8.48" lower = "0.0" upper = "2.00"/>
        <mimic joint="j02" multiplier="0.75" offset="0"/>
        <joint_properties friction="0.0"/>
    </joint>

    <joint name="if_tip" type="fixed">
        <origin xyz="-0.010  -0.048 0.014499" rpy="0 0 0 " />
        <parent link="tip_base" />
        <child link="fingertip_if" />
    </joint>

    <link name="if_tip_center">
        <visual>
            <origin xyz="0 0 0" rpy="0 0 0 " />
            <geometry>
                <sphere radius="0.01"/>
            </geometry>
            <material name="tip_base_material">
                <color rgba="1  0 0 1.0"/>
            </material>
        </visual>
    </link>
    <joint name="if_tip_center_joint" type="fixed">
        <parent link="fingertip_if" />
        <child link="if_tip_center" />
        <!-- <origin rpy="0.00000 0.00000 0.00000" xyz="0 0 -0.07" /> -->
        <origin xyz="0 0 0" rpy="-1.570796326794896558 0 -1.570796326794896558" />
    </joint>

    <link name="if_dip_center">
        <visual>
            <origin xyz="0 0 0" rpy="0 0 0 " />
            <geometry>
                <sphere radius="0.015"/>
            </geometry>
            <material name="tip_base_material">
                <color rgba="1  0 0 1.0"/>
            </material>
        </visual>
    </link>
    <joint name="if_dip_center_joint" type="fixed">
        <parent link="tip_base" />
        <child link="if_dip_center" />
        <origin xyz="0.022 0 0.014499" rpy="0 0 0" />
    </joint>


    <link name="mcp_joint_2">
        <visual>
            <origin xyz="0.0084069022611744960438 0.0077662438597169954416 0.014657354985032913786" rpy="0 0 0" />
            <geometry>
                <mesh filename="./meshes/mcp_joint.stl"/>
            </geometry>
            <material name="mcp_joint_material">
                <color rgba="0.86666666666666669627 0.86666666666666669627 0.050980392156862744391 1.0"/>
            </material>
        </visual>
        <!-- <collision>
            <origin xyz="0.0084069022611744960438 0.0077662438597169954416 0.014657354985032913786" rpy="0 0 0" />
            <geometry>
                <mesh filename="./meshes/mcp_joint.stl"/>
            </geometry>
        </collision> -->
        <inertial>
            <origin xyz="0 0 0" rpy="0 0 0"/>
            <mass value="0.044" />
            <inertia ixx="0.000011499" ixy="0.000003049" ixz="0.000000121" iyy="0.000007796" iyz="0.000000112" izz="0.000014759" />
        </inertial>
    </link>

    <link name="pip_2">
        <visual>
            <origin xyz="0.0096433630922713280131 0.00029999999999999471534 0.00078403401041737645627" rpy="-1.570796326794896558 -1.570796326794896336 0" />
            <geometry>
                <mesh filename="./meshes/pip.stl"/>
            </geometry>
            <material name="pip_material">
                <color rgba="0.74901960784313725839 0.74901960784313725839 0.74901960784313725839 1.0"/>
            </material>
        </visual>
        <!-- <collision>
            <origin xyz="0.0096433630922713280131 0.00029999999999999471534 0.00078403401041737645627" rpy="-1.570796326794896558 -1.570796326794896336 0" />
            <geometry>
                <mesh filename="./meshes/pip.stl"/>
            </geometry>
        </collision> -->
        <inertial>
            <origin xyz="0 0 0" rpy="0 0 0"/>
            <mass value="0.032" />
            <inertia ixx="0.000004798" ixy="0.000000012" ixz="0.000000004" iyy="0.000002862" iyz="0.000000011" izz="0.000004234" />
        </inertial>
    </link>

    <link name="dip_2">
        <visual>
            <origin xyz="0.021133352895225002849 -0.0084321191467048653423 0.0097850881620952373519" rpy="-3.141592653589793116 0 0 " />
            <geometry>
                <mesh filename="./meshes/dip.stl"/>
            </geometry>
            <material name="dip_material">
                <color rgba="0.86666666666666669627 0.86666666666666669627 0.050980392156862744391 1.0"/>
            </material>
        </visual>
        <!-- <collision>
            <origin xyz="0.021133352895225002849 -0.0084321191467048653423 0.0097850881620952373519" rpy="-3.141592653589793116 0 0" />
            <geometry>
                <mesh filename="./meshes/dip.stl"/>
            </geometry>
        </collision> -->
        <inertial>
            <origin xyz="0 0 0" rpy="0 0 0"/>
            <mass value="0.037" />
            <inertia ixx="0.000005542" ixy="-0.000000607" ixz="-0.000000017" iyy="0.000005727" iyz="-0.000000023" izz="0.000006682" />
        </inertial>
    </link>

    <link name="tip_base_2">
        <visual>
            <origin xyz="0 -0.014 0.014499" rpy="3.14159 0 0 " />
            <geometry>
                <mesh filename="./meshes/tip_base.stl"/>
            </geometry>
            <material name="tip_base_material">
                <color rgba="0.46777 0.86666666666666669627 0.050980392156862744391 1.0"/>
            </material>
        </visual>
        <!-- <collision>
            <origin xyz="0 -0.014 0.014499" rpy="3.14159 0 0 " />
            <geometry>
                <mesh filename="./meshes/tip_base.stl"/>
            </geometry>
        </collision> -->
        <inertial>
            <origin xyz="0 0 0" rpy="0 0 0"/>
            <mass value="0.008" />
            <inertia ixx="0.000003368" ixy="0.000000115" ixz="0" iyy="0.000001556" iyz="0" izz="0.000002863" />
        </inertial>
    </link>

    <link name="fingertip_mf">
        <visual>
            <origin xyz="0 0 0" rpy="3.14159 0 -1.57080" />
            <geometry>
                <mesh filename="./meshes/DotTip.stl"/>
            </geometry>
            <material name="fingertip_material">
                <color rgba="0.8627 0.7868 0.5568 1.0"/>
            </material>
        </visual>
        <!-- <collision>
            <origin xyz="0 0 0" rpy="3.14159 0 -1.57080"/>
            <geometry>
                <mesh filename="./meshes/DotTip.stl"/>
            </geometry>
        </collision> -->
        <inertial>
            <origin xyz="0 0 0" rpy="0 0 0"/>
            <mass value="0.016" />
            <inertia ixx="0.000003368" ixy="0.000000115" ixz="0" iyy="0.000001556" iyz="0" izz="0.000002863" />
        </inertial>
    </link>

    <joint name="j04" type="revolute">
        <origin xyz="-0.012200000000000019856 0.038099999999999981104 0.01450000000000000594" rpy="-1.570796326794896558 0 1.5707963267948943376" />
        <parent link="mcp_joint_2" />
        <child link="pip_2" />
        <axis xyz="0 0 -1"/>
        <limit effort="0.95" velocity="8.48" lower = "-0.60" upper = "0.60"/>
        <!-- <limit effort="0.95" velocity="8.48" lower = "-1.047" upper = "1.047"/> -->
        <joint_properties friction="0.0"/>
    </joint>

    <joint name="j05" type="revolute">
        <origin xyz="-0.0070952496528625388569 -0.022392243865100525113 -0.018722403578460229678" rpy="1.570796326794896558 1.570796326794896558 0" />
        <parent link="palm_lower" />
        <child link="mcp_joint_2" />
        <axis xyz="0 0 -1"/>
        <!-- <limit effort="0.95" velocity="8.48" lower = "-0.314" upper = "2.23"/> -->
        <limit effort="0.95" velocity="8.48" lower = "-0.0" upper = "2.23"/>
        <joint_properties friction="0.0"/>
    </joint>

    <joint name="j06" type="revolute">
        <origin xyz="0.014999999999999975159 0.014300000000000000211 -0.013000000000000018485" rpy="1.5707963267948958919 -1.570796326794896336 0" />
        <parent link="pip_2" />
        <child link="dip_2" />
        <axis xyz="0 0 -1"/>
        <limit effort="0.95" velocity="8.48" lower = "0.00" upper = "1.885"/>
        <joint_properties friction="0.0"/>
    </joint>

    <joint name="j07" type="revolute">
        <origin xyz="0 -0.036099999999999854428 0.00020000000000007858714" rpy="0 0 0" />
        <parent link="dip_2" />
        <child link="tip_base_2" />
        <axis xyz="0 0 -1"/>
        <limit effort="0.95" velocity="8.48" lower = "0.0" upper = "2.00"/>
        <mimic joint="j06" multiplier="0.75" offset="0"/>
        <joint_properties friction="0.0"/>
    </joint>

    <joint name="mf_tip" type="fixed">
        <origin xyz="-0.010  -0.048 0.014499" rpy="0 0 0 " />
        <parent link="tip_base_2" />
        <child link="fingertip_mf" />
    </joint>

    <link name="mf_tip_center">
        <visual>
            <origin xyz="0 0 0" rpy="0 0 0 " />
            <geometry>
                <sphere radius="0.01"/>
            </geometry>
            <material name="tip_base_material">
                <color rgba="1  0 0 1.0"/>
            </material>
        </visual>
    </link>
    <joint name="mf_tip_center_joint" type="fixed">
        <parent link="fingertip_mf" />
        <child link="mf_tip_center" />
        <!-- <origin rpy="0.00000 0.00000 0.00000" xyz="0 0 -0.07" /> -->
        <origin xyz="0 -0.0 0" rpy="-1.570796326794896558 0 -1.570796326794896558" />
    </joint>

    <link name="mf_dip_center">
        <visual>
            <origin xyz="0 0 0" rpy="0 0 0 " />
            <geometry>
                <sphere radius="0.015"/>
            </geometry>
            <material name="tip_base_material">
                <color rgba="1  0 0 1.0"/>
            </material>
        </visual>
    </link>
    <joint name="mf_dip_center_joint" type="fixed">
        <parent link="tip_base_2" />
        <child link="mf_dip_center" />
        <origin xyz="0.022 0 0.014499" rpy="0 0 0" />
    </joint>



    <link name="mcp_joint_3">
        <visual>
            <origin xyz="0.0084069022611744995133 0.0077662438597169963089 0.014657354985032913786" rpy="0 0 0" />
            <geometry>
                <mesh filename="./meshes/mcp_joint.stl"/>
            </geometry>
            <material name="mcp_joint_material">
                <color rgba="0.86666666666666669627 0.86666666666666669627 0.050980392156862744391 1.0"/>
            </material>
        </visual>
        <!-- <collision>
            <origin xyz="0.0084069022611744995133 0.0077662438597169963089 0.014657354985032913786" rpy="0 0 0" />
            <geometry>
                <mesh filename="./meshes/mcp_joint.stl"/>
            </geometry>
        </collision> -->
        <inertial>
            <origin xyz="0 0 0" rpy="0 0 0"/>
            <mass value="0.044" />
            <inertia ixx="0.000011499" ixy="0.000003049" ixz="0.000000121" iyy="0.000007796" iyz="0.000000112" izz="0.000014759" />
        </inertial>
    </link>

    <link name="pip_3">
        <visual>
            <origin xyz="0.0096433630922713314826 0.00029999999999998083755 0.00078403401041737645627" rpy="-1.570796326794896558 -1.570796326794896336 0" />
            <geometry>
                <mesh filename="./meshes/pip.stl"/>
            </geometry>
            <material name="pip_material">
                <color rgba="0.74901960784313725839 0.74901960784313725839 0.74901960784313725839 1.0"/>
            </material>
        </visual>
        <!-- <collision>
            <origin xyz="0.0096433630922713314826 0.00029999999999998083755 0.00078403401041737645627" rpy="-1.570796326794896558 -1.570796326794896336 0" />
            <geometry>
                <mesh filename="./meshes/pip.stl"/>
            </geometry>
        </collision> -->
        <inertial>
            <origin xyz="0 0 0" rpy="0 0 0"/>
            <mass value="0.032" />
            <inertia ixx="0.000004798" ixy="0.000000012" ixz="0.000000004" iyy="0.000002862" iyz="0.000000011" izz="0.000004234" />
        </inertial>
    </link>

    <link name="dip_3">
        <visual>
            <origin xyz="0.021133352895225006318 -0.0084321191467048653423 0.0097850881620952373519" rpy="-3.141592653589793116 0 0" />
            <geometry>
                <mesh filename="./meshes/dip.stl"/>
            </geometry>
            <material name="dip_material">
                <color rgba="0.86666666666666669627 0.86666666666666669627 0.050980392156862744391 1.0"/>
            </material>
        </visual>
        <!-- <collision>
            <origin xyz="0.021133352895225006318 -0.0084321191467048653423 0.0097850881620952373519" rpy="-3.141592653589793116 0 0" />
            <geometry>
                <mesh filename="./meshes/dip.stl"/>
            </geometry>
        </collision> -->
        <inertial>
            <origin xyz="0 0 0" rpy="0 0 0"/>
            <mass value="0.037" />
            <inertia ixx="0.000005542" ixy="-0.000000607" ixz="-0.000000017" iyy="0.000005727" iyz="-0.000000023" izz="0.000006682" />
        </inertial>
    </link>

    <link name="tip_base_3">
        <visual>
            <origin xyz="0 -0.014 0.014499" rpy="3.14159 0 0 " />
            <geometry>
                <mesh filename="./meshes/tip_base.stl"/>
            </geometry>
            <material name="tip_base_material">
                <color rgba="0.46777 0.86666666666666669627 0.050980392156862744391 1.0"/>
            </material>
        </visual>
        <!-- <collision>
            <origin xyz="0 -0.014 0.014499" rpy="3.14159 0 0 " />
            <geometry>
                <mesh filename="./meshes/tip_base.stl"/>
            </geometry>
        </collision> -->
        <inertial>
            <origin xyz="0 0 0" rpy="0 0 0"/>
            <mass value="0.008" />
            <inertia ixx="0.000003368" ixy="0.000000115" ixz="0" iyy="0.000001556" iyz="0" izz="0.000002863" />
        </inertial>
    </link>

    <link name="fingertip_rf">
        <visual>
            <!-- <origin xyz="0 -0.017 0.014499" rpy="3.14159 0 -1.57080" /> -->
            <origin xyz="0 0 0 " rpy="3.14159 0 -1.57080" />
            <geometry>
                <mesh filename="./meshes/DotTip.stl"/>
            </geometry>
            <material name="fingertip_material">
                <color rgba="0.8627 0.7868 0.5568 1.0"/>
            </material>
        </visual>
        <!-- <collision>
            <origin xyz="0 0 0 " rpy="3.14159 0 -1.57080" />
            <geometry>
                <mesh filename="./meshes/DotTip.stl"/>
            </geometry>
        </collision> -->
        <inertial>
            <origin xyz="0 0 0" rpy="0 0 0"/>
            <mass value="0.016" />
            <inertia ixx="0.000003368" ixy="0.000000115" ixz="0" iyy="0.000001556" iyz="0" izz="0.000002863" />
        </inertial>
    </link>

    <joint name="j08" type="revolute">
        <origin xyz="-0.012200000000000004244 0.038100000000000001921 0.014499999999999999001" rpy="-1.570796326794896558 0 1.5707963267948943376" />
        <parent link="mcp_joint_3" />
        <child link="pip_3" />
        <axis xyz="0 0 -1"/>
        <limit effort="0.95" velocity="8.48" lower = "-0.60" upper = "1.00"/>
        <!-- <limit effort="0.95" velocity="8.48" lower = "-1.047" upper = "1.047"/> -->
        <joint_properties friction="0.0"/>
    </joint>

    <joint name="j09" type="revolute">
        <origin xyz="-0.0070952454426398371343 -0.067842243865100515521 -0.018722407666402932774" rpy="1.5707963267948950037 1.5707963267948945596 0" />
        <parent link="palm_lower" />
        <child link="mcp_joint_3" />
        <axis xyz="0 0 -1"/>
        <!-- <limit effort="0.95" velocity="8.48" lower = "-0.314" upper = "2.23"/> -->
        <limit effort="0.95" velocity="8.48" lower = "-0.0" upper = "2.23"/>
        <joint_properties friction="0.0"/>
    </joint>

    <joint name="j10" type="revolute">
        <origin xyz="0.014999999999999971689 0.014299999999999951639 -0.012999999999999959505" rpy="1.5707963267948958919 -1.570796326794896336 0" />
        <parent link="pip_3" />
        <child link="dip_3" />
        <axis xyz="0 0 -1"/>
        <limit effort="0.95" velocity="8.48" lower = "0.00" upper = "1.885"/>
        <joint_properties friction="0.0"/>
    </joint>

    <joint name="j11" type="revolute">
        <origin xyz="0 -0.036099999999999868305 0.00020000000000007511769" rpy="0 0 0" />
        <parent link="dip_3" />
        <child link="tip_base_3" />
        <axis xyz="0 0 -1"/>
        <limit effort="0.95" velocity="8.48" lower = "0.0" upper = "2.00"/>    #2.042
        <mimic joint="j10" multiplier="0.75" offset="0"/>
        <joint_properties friction="0.0"/>
    </joint>

    <joint name="rf_tip" type="fixed">
        <origin xyz="-0.010  -0.048 0.014499" rpy="0 0 0 " />
        <parent link="tip_base_3" />
        <child link="fingertip_rf" />
    </joint>

    <link name="rf_tip_center">
        <visual>
            <origin xyz="0 0 0" rpy="0 0 0 " />
            <geometry>
                <sphere radius="0.01"/>
            </geometry>
            <material name="tip_base_material">
                <color rgba="1  0 0 1.0"/>
            </material>
        </visual>
    </link>
    <joint name="rf_tip_center_joint" type="fixed">
        <parent link="fingertip_rf" />
        <child link="rf_tip_center" />
        <!-- <origin rpy="0.00000 0.00000 0.00000" xyz="0 0 -0.07" /> -->
        <origin xyz="0 -0.0 0" rpy="-1.570796326794896558 0 -1.570796326794896558" />
    </joint>

    <link name="rf_dip_center">
        <visual>
            <origin xyz="0 0 0" rpy="0 0 0 " />
            <geometry>
                <sphere radius="0.015"/>
            </geometry>
            <material name="tip_base_material">
                <color rgba="1  0 0 1.0"/>
            </material>
        </visual>
    </link>
    <joint name="rf_dip_center_joint" type="fixed">
        <parent link="tip_base_3" />
        <child link="rf_dip_center" />
        <origin xyz="0.022 0 0.014499" rpy="0 0 0" />
    </joint>


    <link name="pip_4">
        <visual>
            <origin xyz="-0.0053566369077286714317 0.00029999999999999991951 0.00078403401041737819099" rpy="-1.570796326794896558 -1.570796326794896336 0" />
            <geometry>
                <mesh filename="./meshes/pip.stl"/>
            </geometry>
            <material name="pip_material">
                <color rgba="0.74901960784313725839 0.74901960784313725839 0.74901960784313725839 1.0"/>
            </material>
        </visual>
        <!-- <collision>
            <origin xyz="-0.0053566369077286714317 0.00029999999999999991951 0.00078403401041737819099" rpy="-1.570796326794896558 -1.570796326794896336 0" />
            <geometry>
                <mesh filename="./meshes/pip.stl"/>
            </geometry>
        </collision> -->
        <inertial>
            <origin xyz="0 0 0" rpy="0 0 0"/>
            <mass value="0.032" />
            <inertia ixx="0.000004798" ixy="0.000000012" ixz="0.000000004" iyy="0.000002862" iyz="0.000000011" izz="0.000004234" />
        </inertial>
    </link>

    <link name="thumb_pip">
        <visual>
            <origin xyz="0.011961920770611186859 0 -0.015852648956664199681" rpy="1.570796326794896558 0 0" />
            <geometry>
                <mesh filename="./meshes/thumb_pip.stl"/>
            </geometry>
            <material name="thumb_pip_material">
                <color rgba="0.86666666666666669627 0.86666666666666669627 0.050980392156862744391 1.0"/>
            </material>
        </visual>
        <!-- <collision>
            <origin xyz="0.011961920770611186859 0 -0.015852648956664199681" rpy="1.570796326794896558 0 0" />
            <geometry>
                <mesh filename="./meshes/thumb_pip.stl"/>
            </geometry>
        </collision> -->
        <inertial>
            <origin xyz="0 0 0" rpy="0 0 0"/>
            <mass value="0.003" />
            <inertia ixx="0.000000593" ixy="0" ixz="0" iyy="0.000000549" iyz="0" izz="0.000000224" />
        </inertial>
    </link>

    <link name="thumb_dip">
        <visual>
            <origin xyz="0.043968715707239175439 0.057952952973709198625 -0.0086286764493694757122" rpy="0 0 0" />
            <geometry>
                <mesh filename="./meshes/thumb_dip.stl"/>
            </geometry>
            <material name="thumb_dip_material">
                <color rgba="0.86666666666666669627 0.86666666666666669627 0.050980392156862744391 1.0"/>
            </material>
        </visual>
        <!-- <collision>
            <origin xyz="0.043968715707239175439 0.057952952973709198625 -0.0086286764493694757122" rpy="0 0 0" />
            <geometry>
                <mesh filename="./meshes/thumb_dip.stl"/>
            </geometry>
        </collision> -->
        <inertial>
            <origin xyz="0 0 0" rpy="0 0 0"/>
            <mass value="0.038" />
            <inertia ixx="0.000008474" ixy="0.000000241" ixz="0.000000026" iyy="0.000003841" iyz="0.000000025" izz="0.000007679" />
        </inertial>
    </link>

    <link name="thumb_tip_base">
        <visual>
            <origin xyz="0 0 -0.0065" rpy="0 0 0 " />
            <geometry>
                <mesh filename="./meshes/thumb_tip_base.stl"/>
            </geometry>
            <material name="tip_base_material">
                <color rgba="0.46777 0.86666666666666669627 0.050980392156862744391 1.0"/>
            </material>
        </visual>
        <!-- <collision>
            <origin xyz="0 0 -0.0065" rpy="0 0 0 " />
            <geometry>
                <mesh filename="./meshes/thumb_tip_base.stl"/>
            </geometry>
        </collision> -->
        <inertial>
            <origin xyz="0 0 0" rpy="0 0 0"/>
            <mass value="0.008" />
            <inertia ixx="0.000003368" ixy="0.000000115" ixz="0" iyy="0.000001556" iyz="0" izz="0.000002863" />
        </inertial>
    </link>

    <link name="tf_dip_center">
        <visual>
            <origin xyz="0 0 0" rpy="0 0 0 " />
            <geometry>
                <sphere radius="0.015"/>
            </geometry>
            <material name="tip_base_material">
                <color rgba="1  0 0 1.0"/>
            </material>
        </visual>
    </link>
    <joint name="tf_dip_center_joint" type="fixed">
        <parent link="thumb_tip_base" />
        <child link="tf_dip_center" />
        <origin xyz="0 0 -0.014499" rpy="0 0 0" />
    </joint>

    <link name="thumb_fingertip">
        <visual>
            <origin xyz="0 0 0 " rpy="3.14159 0 -1.57080" />
            <geometry>
                <mesh filename="./meshes/DotTip-thumb.stl"/>
            </geometry>
            <material name="fingertip_material">
                <color rgba="0.8627 0.7868 0.5568 1.0"/>
            </material>
        </visual>
        <!-- <collision>
            <origin xyz="0 0 0 " rpy="3.14159 0 -1.57080" />
            <geometry>
                <mesh filename="./meshes/DotTip-thumb.stl"/>
            </geometry>
        </collision> -->
        <inertial>
            <origin xyz="0 0 0" rpy="0 0 0"/>
            <mass value="0.016" />
            <inertia ixx="0.000003368" ixy="0.000000115" ixz="0" iyy="0.000001556" iyz="0" izz="0.000002863" />
        </inertial>
    </link>


    <!-- <link name="thumb_fingertip">
        <visual>
            <origin xyz="0.062559538462667388381 0.078459682911396988469 0.048992911807332215068" rpy="0 0 0" />
            <geometry>
                <mesh filename="./meshes/thumb_fingertip.stl"/>
            </geometry>
            <material name="thumb_fingertip_material">
                <color rgba="0.60392156862745094426 0.14901960784313725283 0.14901960784313725283 1.0"/>
            </material>
        </visual>
        <collision>
            <origin xyz="0.062559538462667388381 0.078459682911396988469 0.048992911807332215068" rpy="0 0 0" />
            <geometry>
                <mesh filename="./meshes/thumb_fingertip.stl"/>
            </geometry>
        </collision>
        <inertial>
            <origin xyz="0 0 0" rpy="0 0 0"/>
            <mass value="0.049" />
            <inertia ixx="0.000020372" ixy="-0.000000489" ixz="-0.00000003" iyy="0.000004336" iyz="-0.000000097" izz="0.000019845" />
        </inertial>
    </link> -->

    <joint name="j12" type="revolute">
        <origin xyz="-0.069395249652862533996 -0.0012422438651005258004 -0.021622403578460215601" rpy="0 1.5707963267948956698 0" />
        <parent link="palm_lower" />
        <child link="pip_4" />
        <axis xyz="0 0 -1"/>
        <limit effort="0.95" velocity="8.48" lower = "-0.349" upper = "2.094"/>
        <joint_properties friction="0.0"/>
    </joint>

    <joint name="j13" type="revolute">
        <origin xyz="0 0.014300000000000005415 -0.013000000000000011546" rpy="1.5707963267948958919 -1.570796326794896336 0" />
        <parent link="pip_4" />
        <child link="thumb_pip" />
        <axis xyz="0 0 -1"/>
        <!-- <limit effort="0.95" velocity="8.48" lower = "-0.47" upper = "2.443"/> -->
        <limit effort="0.95" velocity="8.48" lower = "-0.47" upper = "1.20"/>
        <joint_properties friction="0.0"/>
    </joint>

    <joint name="j14" type="revolute">
        <origin xyz="0 0.014499999999999966041 -0.017000000000000053263" rpy="-1.570796326794896558 0 0" />
        <parent link="thumb_pip" />
        <child link="thumb_dip" />
        <axis xyz="0 0 -1"/>
        <limit effort="0.95" velocity="8.48" lower = "-1.20" upper = "1.90"/>
        <joint_properties friction="0.0"/>
    </joint>

    <joint name="j15" type="revolute">
        <origin xyz="0 0.046599999999999863753 0.00019999999999997710581" rpy="0 0 3.141592653589793116" />
        <parent link="thumb_dip" />
        <child link="thumb_tip_base" />
        <axis xyz="0 0 -1"/>
        <!-- <limit effort="0.95" velocity="8.48" lower = "-1.34" upper = "1.88"/> -->
        <limit effort="0.95" velocity="8.48" lower = "-0.5" upper = "1.88"/>
        <joint_properties friction="0.0"/>
    </joint>

    <joint name="tf_tip" type="fixed">
        <origin xyz="-0.0102  -0.0645 -0.0145" rpy="0 0 0 " />
        <parent link="thumb_tip_base" />
        <child link="thumb_fingertip" />
    </joint>

    <link name="tf_tip_center">
        <visual>
            <origin xyz="0 0 0" rpy="0 0 0 " />
            <geometry>
                <sphere radius="0.01"/>
            </geometry>
            <material name="tip_base_material">
                <color rgba="1  0 0 1.0"/>
            </material>
        </visual>
    </link>
    <joint name="tf_tip_center_joint" type="fixed">
        <parent link="thumb_fingertip" />
        <child link="tf_tip_center" />
        <!-- <origin rpy="0.00000 0.00000 0.00000" xyz="0 0 -0.07" /> -->
        <origin xyz="0 0.0 0" rpy="-1.570796326794896558 0 -1.570796326794896558" />
    </joint>

</robot>
